Workbook

Sheet 1. Instructions
A1: Eelgrass Workshop — Digital Data Sheet
A2: Companion to WWF-Canada, Measuring Carbon in Coastal Sediments (2026), and Part 4 of the Blue Carbon Eelgrass Workshop.
A5: HOW TO USE THIS WORKBOOK
A6: Sheet 2 — Plot & Core Log | B6: One row per CORE. Enter plot/core notes, the two compaction depths and (if you stratified) the stratum. The compaction factor calculates itself. Enter a corer diameter there only for a core taken with a different tube from the one below.
A7: Sheet 3 — Sample Data | B7: One row per SLICE. Enter the field columns before you leave site, then add the lab columns when results come back. Everything else calculates, and the Slice check column tells you what is missing or inconsistent.
A8: Sheet 4 — Core Summary | B8: Per-core totals and standard depth increments. Fully automatic — nothing to type here.
A10: YOUR CORER
A11: Corer internal diameter (cm) | B11: 7.6
A12: About the diameter | B12: Measured inside the tube with calipers — not the nominal pipe size (see THINGS THAT CATCH PEOPLE OUT). Used for every core, unless Sheet 2 column J gives a different value for that core. Leave it blank and the slices are flagged: the volume, and so the bulk density, cannot be calculated.
A14: COLOUR KEY
A15: Yellow fill / blue text | B15: You type here: data from the field data sheet, or from the lab.
A16: Grey fill / black text | B16: Calculated. Do not type over these — you will break the column.
A17: Green text | B17: Pulled from another sheet in this workbook.
A19: THE FIVE BANDS ON SHEET 3
A20: 1. Data from the field | B20: Copy directly from the field data sheet.
A21: 2. Calculated before the lab | B21: Depth interval, compaction-corrected (in-situ) depths, and sample volume. You need the volume to hand to the lab, or to compute bulk density yourself.
A22: 3. Measured by the lab | B22: Wet weight, dry weight of the whole slice, the carbon value, and what that carbon value is (column O: OC, TC or LOI).
A23: 4. Calculated after the lab | B23: Bulk density, organic carbon, carbon density, carbon stock per slice, and the share of each slice's stock that falls in each standard depth increment.
A24: 5. Check | B24: One plain-language message per slice. A core is only totalled when all its slices say OK.
A26: CARBON: WHAT THE LAB MEASURED
A27: OC | B27: Organic carbon measured directly — elemental analyser on acid-treated sample, or total carbon minus measured inorganic carbon. Used as is.
A28: TC | B28: Total carbon. Includes shell and other carbonate, which is not organic carbon. It is not used: ask the lab for inorganic carbon (IC) and enter OC = TC − IC instead.
A29: LOI | B29: Loss on ignition (% organic matter). Converted to organic carbon with the equation below: OC% = intercept + slope × LOI%. A value that would convert to below zero is outside the equation's range and is flagged, not set to zero.
A30: LOI intercept | B30: -0.197 | C30: Example: local calibration from the 16 slices in these cores with both elemental OC and LOI (r² = 0.73).
A31: LOI slope | B31: 0.32
A32: Where the equation comes from | B32: Best: your own calibration — run elemental analysis on a subset of the same samples and fit OC against LOI. Otherwise use a published seagrass equation and cite it. Leave these blank and LOI rows stay unconverted (the Slice check says so). Report the equation you used.
A34: UNITS
A35: Depths | B35: centimetres (cm)
A36: Weights | B36: grams (g). Some labs report kilograms — convert before typing.
A37: Volume | B37: cubic centimetres (cm3)
A38: Carbon value | B38: percent of dry mass (0–100). If the lab reports a fraction (0–1), multiply by 100.
A39: Dry bulk density | B39: g/cm3 = dry weight of the whole slice ÷ slice volume
A40: Carbon stock | B40: g C/cm2 per slice (field guide Eq 4) and kg C/m2 (Eq 6). × 10 gives Mg C/ha.
A42: STANDARD DEPTH INCREMENTS
A43: 0–15, 15–30, 30–50, 50–100 cm | B43: Measured on in-situ depths. A slice that crosses a boundary is split in proportion to how much of it lies on each side. Sheet 4 only reports an increment when the core reaches its bottom; otherwise it says 'partial' or 'not reached'.
A45: THE ANALYSIS (Part 4)
A46: No export needed | B46: The R workflow reads this workbook directly. Keep the tab names and the header rows as they are, save as .xlsx (in Google Sheets: File → Download → Microsoft Excel), and point the workflow's settings file at it.
A48: THINGS THAT CATCH PEOPLE OUT
A49: Measure your actual corer diameter | B49: Nominal pipe size is not internal diameter. A '3 inch' Schedule 40 PVC pipe has an internal diameter noticeably larger than 7.62 cm. Volume sits in the denominator of bulk density, so an assumed diameter biases EVERY carbon stock in the dataset. Measure the ID with calipers and enter it under YOUR CORER above (and on the field data sheet).
A50: Compaction corrects depths, not stocks | B50: Carbon stock per slice uses the MEASURED interval and the recovered-slice volume. The dry mass in the tube already came from a taller in-situ column, so multiplying by the compaction factor as well would double-count it. The corrected depths (columns I–J) tell you which in-situ depth each slice represents, which is what the depth increments need.
...

Sheet 2. Plot & Core Log
A1: Plot & Core Log — one row per core
A2: Enter one row for every core you collect. Core ID must be unique and must match exactly what you type on Sheet 3 — the sample rows look up their compaction factor and corer diameter from here.
A4: Plot & core identification | J4: Coring measurements | M4: Calculated | P4: Design & notes | S4: Corer used
A5: Plot ID | B5: Core ID | C5: Date | D5: Time | E5: Study area / site | F5: Latitude | G5: Longitude | H5: Photo series ID | I5: Weather / tidal conditions | J5: Corer internal diameter (cm) only if different from Instructions | K5: Outside depth (cm) = depth of corer inserted | L5: Inside depth (cm) = length of core extracted | M5: Compaction factor = outside / inside | N5: Compaction (cm) = outside - inside | O5: QC check | P5: Stratum (code) e.g. SG | Q5: Compaction not measured? enter: assume none | R5: Core notes | S5: Corer diameter used (cm) | T5: Diameter from
A6: S5 | B6: COW-S5 | E6: Cowichan Estuary, BC — eelgrass | F6: 48.76117 | G6: -123.62483 | M6: =IF(AND($K6<>"",$L6<>""),$K6/$L6,IF(LOWER(TRIM($Q6))="assume none",1,"")) -> 1 | N6: =IF(OR($K6="",$L6=""),"",$K6-$L6) | O6: =IF($B6="","",IF(COUNTIF($B$6:$B$35,$B6)>1,"CHECK: duplicate Core ID",IF($S6="","CHECK: corer diameter missing",IF(AND($K6="",$L6=""),IF($M6=1,"ASSUMED: no compaction (not measured)","CHECK: compaction not recorded"),IF(OR($K6="",$L6=""),"CHECK: one depth missing",IF($L6>$K6,"CHECK: extracted > inserted",IF($M6>1.5,"CHECK: >50% compaction","OK"))))))) -> ASSUMED: no compaction (not measured) | P6: SG | Q6: assume none | R6: Published core (Douglas et al. 2022, via Janousek et al. 2025). Sampling date and insertion depth not published; source reports no compaction observed. | S6: =IF($B6="","",IF($J6<>"",$J6,IF(CORER_DIAMETER_CM<>"",CORER_DIAMETER_CM,""))) -> 7.6 | T6: =IF($B6="","",IF($J6<>"","this core",IF(CORER_DIAMETER_CM<>"","Instructions","missing"))) -> Instructions
A7: S6 | B7: COW-S6 | E7: Cowichan Estuary, BC — eelgrass | F7: 48.7615 | G7: -123.62467 | M7: =IF(AND($K7<>"",$L7<>""),$K7/$L7,IF(LOWER(TRIM($Q7))="assume none",1,"")) -> 1 | N7: =IF(OR($K7="",$L7=""),"",$K7-$L7) | O7: =IF($B7="","",IF(COUNTIF($B$6:$B$35,$B7)>1,"CHECK: duplicate Core ID",IF($S7="","CHECK: corer diameter missing",IF(AND($K7="",$L7=""),IF($M7=1,"ASSUMED: no compaction (not measured)","CHECK: compaction not recorded"),IF(OR($K7="",$L7=""),"CHECK: one depth missing",IF($L7>$K7,"CHECK: extracted > inserted",IF($M7>1.5,"CHECK: >50% compaction","OK"))))))) -> ASSUMED: no compaction (not measured) | P7: SG | Q7: assume none | R7: Published core (Douglas et al. 2022, via Janousek et al. 2025). Sampling date and insertion depth not published; source reports no compaction observed. | S7: =IF($B7="","",IF($J7<>"",$J7,IF(CORER_DIAMETER_CM<>"",CORER_DIAMETER_CM,""))) -> 7.6 | T7: =IF($B7="","",IF($J7<>"","this core",IF(CORER_DIAMETER_CM<>"","Instructions","missing"))) -> Instructions
A8: S7 | B8: COW-S7 | E8: Cowichan Estuary, BC — eelgrass | F8: 48.762 | G8: -123.62433 | M8: =IF(AND($K8<>"",$L8<>""),$K8/$L8,IF(LOWER(TRIM($Q8))="assume none",1,"")) -> 1 | N8: =IF(OR($K8="",$L8=""),"",$K8-$L8) | O8: =IF($B8="","",IF(COUNTIF($B$6:$B$35,$B8)>1,"CHECK: duplicate Core ID",IF($S8="","CHECK: corer diameter missing",IF(AND($K8="",$L8=""),IF($M8=1,"ASSUMED: no compaction (not measured)","CHECK: compaction not recorded"),IF(OR($K8="",$L8=""),"CHECK: one depth missing",IF($L8>$K8,"CHECK: extracted > inserted",IF($M8>1.5,"CHECK: >50% compaction","OK"))))))) -> ASSUMED: no compaction (not measured) | P8: SG | Q8: assume none | R8: Published core (Douglas et al. 2022, via Janousek et al. 2025). Sampling date and insertion depth not published; source reports no compaction observed. | S8: =IF($B8="","",IF($J8<>"",$J8,IF(CORER_DIAMETER_CM<>"",CORER_DIAMETER_CM,""))) -> 7.6 | T8: =IF($B8="","",IF($J8<>"","this core",IF(CORER_DIAMETER_CM<>"","Instructions","missing"))) -> Instructions
M9: =IF(AND($K9<>"",$L9<>""),$K9/$L9,IF(LOWER(TRIM($Q9))="assume none",1,"")) | N9: =IF(OR($K9="",$L9=""),"",$K9-$L9) | O9: =IF($B9="","",IF(COUNTIF($B$6:$B$35,$B9)>1,"CHECK: duplicate Core ID",IF($S9="","CHECK: corer diameter missing",IF(AND($K9="",$L9=""),IF($M9=1,"ASSUMED: no compaction (not measured)","CHECK: compaction not recorded"),IF(OR($K9="",$L9=""),"CHECK: one depth missing",IF($L9>$K9,"CHECK: extracted > inserted",IF($M9>1.5,"CHECK: >50% compaction","OK"))))))) | S9: =IF($B9="","",IF($J9<>"",$J9,IF(CORER_DIAMETER_CM<>"",CORER_DIAMETER_CM,""))) | T9: =IF($B9="","",IF($J9<>"","this core",IF(CORER_DIAMETER_CM<>"","Instructions","missing")))
M10: =IF(AND($K10<>"",$L10<>""),$K10/$L10,IF(LOWER(TRIM($Q10))="assume none",1,"")) | N10: =IF(OR($K10="",$L10=""),"",$K10-$L10) | O10: =IF($B10="","",IF(COUNTIF($B$6:$B$35,$B10)>1,"CHECK: duplicate Core ID",IF($S10="","CHECK: corer diameter missing",IF(AND($K10="",$L10=""),IF($M10=1,"ASSUMED: no compaction (not measured)","CHECK: compaction not recorded"),IF(OR($K10="",$L10=""),"CHECK: one depth missing",IF($L10>$K10,"CHECK: extracted > inserted",IF($M10>1.5,"CHECK: >50% compaction","OK"))))))) | S10: =IF($B10="","",IF($J10<>"",$J10,IF(CORER_DIAMETER_CM<>"",CORER_DIAMETER_CM,""))) | T10: =IF($B10="","",IF($J10<>"","this core",IF(CORER_DIAMETER_CM<>"","Instructions","missing")))
M11: =IF(AND($K11<>"",$L11<>""),$K11/$L11,IF(LOWER(TRIM($Q11))="assume none",1,"")) | N11: =IF(OR($K11="",$L11=""),"",$K11-$L11) | O11: =IF($B11="","",IF(COUNTIF($B$6:$B$35,$B11)>1,"CHECK: duplicate Core ID",IF($S11="","CHECK: corer diameter missing",IF(AND($K11="",$L11=""),IF($M11=1,"ASSUMED: no compaction (not measured)","CHECK: compaction not recorded"),IF(OR($K11="",$L11=""),"CHECK: one depth missing",IF($L11>$K11,"CHECK: extracted > inserted",IF($M11>1.5,"CHECK: >50% compaction","OK"))))))) | S11: =IF($B11="","",IF($J11<>"",$J11,IF(CORER_DIAMETER_CM<>"",CORER_DIAMETER_CM,""))) | T11: =IF($B11="","",IF($J11<>"","this core",IF(CORER_DIAMETER_CM<>"","Instructions","missing")))
M12: =IF(AND($K12<>"",$L12<>""),$K12/$L12,IF(LOWER(TRIM($Q12))="assume none",1,"")) | N12: =IF(OR($K12="",$L12=""),"",$K12-$L12) | O12: =IF($B12="","",IF(COUNTIF($B$6:$B$35,$B12)>1,"CHECK: duplicate Core ID",IF($S12="","CHECK: corer diameter missing",IF(AND($K12="",$L12=""),IF($M12=1,"ASSUMED: no compaction (not measured)","CHECK: compaction not recorded"),IF(OR($K12="",$L12=""),"CHECK: one depth missing",IF($L12>$K12,"CHECK: extracted > inserted",IF($M12>1.5,"CHECK: >50% compaction","OK"))))))) | S12: =IF($B12="","",IF($J12<>"",$J12,IF(CORER_DIAMETER_CM<>"",CORER_DIAMETER_CM,""))) | T12: =IF($B12="","",IF($J12<>"","this core",IF(CORER_DIAMETER_CM<>"","Instructions","missing")))
M13: =IF(AND($K13<>"",$L13<>""),$K13/$L13,IF(LOWER(TRIM($Q13))="assume none",1,"")) | N13: =IF(OR($K13="",$L13=""),"",$K13-$L13) | O13: =IF($B13="","",IF(COUNTIF($B$6:$B$35,$B13)>1,"CHECK: duplicate Core ID",IF($S13="","CHECK: corer diameter missing",IF(AND($K13="",$L13=""),IF($M13=1,"ASSUMED: no compaction (not measured)","CHECK: compaction not recorded"),IF(OR($K13="",$L13=""),"CHECK: one depth missing",IF($L13>$K13,"CHECK: extracted > inserted",IF($M13>1.5,"CHECK: >50% compaction","OK"))))))) | S13: =IF($B13="","",IF($J13<>"",$J13,IF(CORER_DIAMETER_CM<>"",CORER_DIAMETER_CM,""))) | T13: =IF($B13="","",IF($J13<>"","this core",IF(CORER_DIAMETER_CM<>"","Instructions","missing")))
M14: =IF(AND($K14<>"",$L14<>""),$K14/$L14,IF(LOWER(TRIM($Q14))="assume none",1,"")) | N14: =IF(OR($K14="",$L14=""),"",$K14-$L14) | O14: =IF($B14="","",IF(COUNTIF($B$6:$B$35,$B14)>1,"CHECK: duplicate Core ID",IF($S14="","CHECK: corer diameter missing",IF(AND($K14="",$L14=""),IF($M14=1,"ASSUMED: no compaction (not measured)","CHECK: compaction not recorded"),IF(OR($K14="",$L14=""),"CHECK: one depth missing",IF($L14>$K14,"CHECK: extracted > inserted",IF($M14>1.5,"CHECK: >50% compaction","OK"))))))) | S14: =IF($B14="","",IF($J14<>"",$J14,IF(CORER_DIAMETER_CM<>"",CORER_DIAMETER_CM,""))) | T14: =IF($B14="","",IF($J14<>"","this core",IF(CORER_DIAMETER_CM<>"","Instructions","missing")))
M15: =IF(AND($K15<>"",$L15<>""),$K15/$L15,IF(LOWER(TRIM($Q15))="assume none",1,"")) | N15: =IF(OR($K15="",$L15=""),"",$K15-$L15) | O15: =IF($B15="","",IF(COUNTIF($B$6:$B$35,$B15)>1,"CHECK: duplicate Core ID",IF($S15="","CHECK: corer diameter missing",IF(AND($K15="",$L15=""),IF($M15=1,"ASSUMED: no compaction (not measured)","CHECK: compaction not recorded"),IF(OR($K15="",$L15=""),"CHECK: one depth missing",IF($L15>$K15,"CHECK: extracted > inserted",IF($M15>1.5,"CHECK: >50% compaction","OK"))))))) | S15: =IF($B15="","",IF($J15<>"",$J15,IF(CORER_DIAMETER_CM<>"",CORER_DIAMETER_CM,""))) | T15: =IF($B15="","",IF($J15<>"","this core",IF(CORER_DIAMETER_CM<>"","Instructions","missing")))
M16: =IF(AND($K16<>"",$L16<>""),$K16/$L16,IF(LOWER(TRIM($Q16))="assume none",1,"")) | N16: =IF(OR($K16="",$L16=""),"",$K16-$L16) | O16: =IF($B16="","",IF(COUNTIF($B$6:$B$35,$B16)>1,"CHECK: duplicate Core ID",IF($S16="","CHECK: corer diameter missing",IF(AND($K16="",$L16=""),IF($M16=1,"ASSUMED: no compaction (not measured)","CHECK: compaction not recorded"),IF(OR($K16="",$L16=""),"CHECK: one depth missing",IF($L16>$K16,"CHECK: extracted > inserted",IF($M16>1.5,"CHECK: >50% compaction","OK"))))))) | S16: =IF($B16="","",IF($J16<>"",$J16,IF(CORER_DIAMETER_CM<>"",CORER_DIAMETER_CM,""))) | T16: =IF($B16="","",IF($J16<>"","this core",IF(CORER_DIAMETER_CM<>"","Instructions","missing")))
M17: =IF(AND($K17<>"",$L17<>""),$K17/$L17,IF(LOWER(TRIM($Q17))="assume none",1,"")) | N17: =IF(OR($K17="",$L17=""),"",$K17-$L17) | O17: =IF($B17="","",IF(COUNTIF($B$6:$B$35,$B17)>1,"CHECK: duplicate Core ID",IF($S17="","CHECK: corer diameter missing",IF(AND($K17="",$L17=""),IF($M17=1,"ASSUMED: no compaction (not measured)","CHECK: compaction not recorded"),IF(OR($K17="",$L17=""),"CHECK: one depth missing",IF($L17>$K17,"CHECK: extracted > inserted",IF($M17>1.5,"CHECK: >50% compaction","OK"))))))) | S17: =IF($B17="","",IF($J17<>"",$J17,IF(CORER_DIAMETER_CM<>"",CORER_DIAMETER_CM,""))) | T17: =IF($B17="","",IF($J17<>"","this core",IF(CORER_DIAMETER_CM<>"","Instructions","missing")))
M18: =IF(AND($K18<>"",$L18<>""),$K18/$L18,IF(LOWER(TRIM($Q18))="assume none",1,"")) | N18: =IF(OR($K18="",$L18=""),"",$K18-$L18) | O18: =IF($B18="","",IF(COUNTIF($B$6:$B$35,$B18)>1,"CHECK: duplicate Core ID",IF($S18="","CHECK: corer diameter missing",IF(AND($K18="",$L18=""),IF($M18=1,"ASSUMED: no compaction (not measured)","CHECK: compaction not recorded"),IF(OR($K18="",$L18=""),"CHECK: one depth missing",IF($L18>$K18,"CHECK: extracted > inserted",IF($M18>1.5,"CHECK: >50% compaction","OK"))))))) | S18: =IF($B18="","",IF($J18<>"",$J18,IF(CORER_DIAMETER_CM<>"",CORER_DIAMETER_CM,""))) | T18: =IF($B18="","",IF($J18<>"","this core",IF(CORER_DIAMETER_CM<>"","Instructions","missing")))
M19: =IF(AND($K19<>"",$L19<>""),$K19/$L19,IF(LOWER(TRIM($Q19))="assume none",1,"")) | N19: =IF(OR($K19="",$L19=""),"",$K19-$L19) | O19: =IF($B19="","",IF(COUNTIF($B$6:$B$35,$B19)>1,"CHECK: duplicate Core ID",IF($S19="","CHECK: corer diameter missing",IF(AND($K19="",$L19=""),IF($M19=1,"ASSUMED: no compaction (not measured)","CHECK: compaction not recorded"),IF(OR($K19="",$L19=""),"CHECK: one depth missing",IF($L19>$K19,"CHECK: extracted > inserted",IF($M19>1.5,"CHECK: >50% compaction","OK"))))))) | S19: =IF($B19="","",IF($J19<>"",$J19,IF(CORER_DIAMETER_CM<>"",CORER_DIAMETER_CM,""))) | T19: =IF($B19="","",IF($J19<>"","this core",IF(CORER_DIAMETER_CM<>"","Instructions","missing")))
M20: =IF(AND($K20<>"",$L20<>""),$K20/$L20,IF(LOWER(TRIM($Q20))="assume none",1,"")) | N20: =IF(OR($K20="",$L20=""),"",$K20-$L20) | O20: =IF($B20="","",IF(COUNTIF($B$6:$B$35,$B20)>1,"CHECK: duplicate Core ID",IF($S20="","CHECK: corer diameter missing",IF(AND($K20="",$L20=""),IF($M20=1,"ASSUMED: no compaction (not measured)","CHECK: compaction not recorded"),IF(OR($K20="",$L20=""),"CHECK: one depth missing",IF($L20>$K20,"CHECK: extracted > inserted",IF($M20>1.5,"CHECK: >50% compaction","OK"))))))) | S20: =IF($B20="","",IF($J20<>"",$J20,IF(CORER_DIAMETER_CM<>"",CORER_DIAMETER_CM,""))) | T20: =IF($B20="","",IF($J20<>"","this core",IF(CORER_DIAMETER_CM<>"","Instructions","missing")))
... M35: =IF(AND($K35<>"",$L35<>""),$K35/$L35,IF(LOWER(TRIM($Q35))="assume none",1,"")) | N35: =IF(OR($K35="",$L35=""),"",$K35-$L35) | O35: =IF($B35="","",IF(COUNTIF($B$6:$B$35,$B35)>1,"CHECK: duplicate Core ID",IF($S35="","CHECK: corer diameter missing",IF(AND($K35="",$L35=""),IF($M35=1,"ASSUMED: no compaction (not measured)","CHECK: compaction not recorded"),IF(OR($K35="",$L35=""),"CHECK: one depth missing",IF($L35>$K35,"CHECK: extracted > inserted",IF($M35>1.5,"CHECK: >50% compaction","OK"))))))) | S35: =IF($B35="","",IF($J35<>"",$J35,IF(CORER_DIAMETER_CM<>"",CORER_DIAMETER_CM,""))) | T35: =IF($B35="","",IF($J35<>"","this core",IF(CORER_DIAMETER_CM<>"","Instructions","missing")))
A37: Definitions — outside vs inside depth
A38: Outside depth = how far the corer was driven into the sediment (the datasheet's 'Depth of corer inserted'). Inside depth = the length of core actually recovered in the tube ('Length of core extracted'). Compaction factor = outside / inside: the number a measured depth is multiplied by to give its true in-situ depth. If compaction was not measured, leave both blank and type 'assume none' in column Q only if you have a reason to believe there was none — the QC check will then say ASSUMED, never OK. Stratum: the code from your sampling design (Part 2), e.g. SG; leave blank if you did not stratify. Corer diameter: enter it once on the Instructions tab (YOUR CORER); fill column J only for a core taken with a different tube. Column S shows the diameter used.

Sheet 3. Sample Data
A1: Sample Data — one row per slice
A2: Type only in the yellow columns. Core ID must match Sheet 2 exactly. Enter the carbon value as a percent of dry mass (0.9 means 0.9%), and say what it is in column O: OC, TC or LOI.
A4: 1. Data from the field | F4: 2. Calculated before the lab | L4: 3. Measured by the lab | P4: 4. Calculated after the lab | AA4: 5. Check
A5: Core ID | B5: Sample ID | C5: Top depth (cm) | D5: Bottom depth (cm) | E5: Notes | F5: Depth interval (cm) | G5: Compaction factor | H5: Corer diameter (cm) | I5: In-situ top depth (cm) | J5: In-situ bottom depth (cm) | K5: Sample volume (cm3) | L5: Wet weight (g) | M5: Dry weight (g) whole slice | N5: Carbon value (% of dry mass) | O5: Carbon measured as OC / TC / LOI | P5: Water content (%) | Q5: Dry bulk density (g/cm3) | R5: Organic carbon (%) | S5: Organic carbon (g/kg) | T5: Carbon density (g C/cm3) | U5: Carbon stock (g C/cm2) | V5: Carbon stock (kg C/m2) | W5: Stock in 0–15 cm (kg C/m2) | X5: Stock in 15–30 cm (kg C/m2) | Y5: Stock in 30–50 cm (kg C/m2) | Z5: Stock in 50–100 cm (kg C/m2) | AA5: Slice check
A6: COW-S5 | B6: 1 | C6: 0 | D6: 1 | E6: OC: elemental analyser, carbonate removed by acid fumigation. Dry weight back-calculated from published bulk density. | F6: =IF(OR($C6="",$D6=""),"",$D6-$C6) -> 1 | G6: =IF($A6="","",IFERROR(INDEX('2. Plot & Core Log'!$M$6:$M$35,MATCH($A6,'2. Plot & Core Log'!$B$6:$B$35,0)),"")) -> 1 | H6: =IF($A6="","",IFERROR(INDEX('2. Plot & Core Log'!$S$6:$S$35,MATCH($A6,'2. Plot & Core Log'!$B$6:$B$35,0)),"")) -> 7.6 | I6: =IF(OR($C6="",$G6=""),"",$C6*$G6) -> 0 | J6: =IF(OR($D6="",$G6=""),"",$D6*$G6) -> 1 | K6: =IF(OR($F6="",$H6=""),"",PI()*(($H6/2)^2)*$F6) -> 45.364598 | M6: 53.98 | N6: 0.9 | O6: OC | P6: =IF(OR($L6="",$M6="",$L6=0),"",(($L6-$M6)/$L6)*100) | Q6: =IF(OR($M6="",$K6="",$K6=0),"",$M6/$K6) -> 1.1899147 | R6: =IF(OR($N6="",$O6=""),"",IF(UPPER($O6)="OC",$N6,IF(UPPER($O6)="LOI",IF(OR(LOI_INTERCEPT="",LOI_SLOPE=""),"",IF(LOI_INTERCEPT+LOI_SLOPE*$N6<0,"",LOI_INTERCEPT+LOI_SLOPE*$N6)),""))) -> 0.9 | S6: =IF($R6="","",$R6*10) -> 9 | T6: =IF(OR($Q6="",$R6=""),"",$Q6*$R6/100) -> 0.010709232 | U6: =IF(OR($T6="",$F6=""),"",$T6*$F6) -> 0.010709232 | V6: =IF($U6="","",$U6*10) -> 0.10709232 | W6: =IF(OR($V6="",$I6="",$J6="",$J6<=$I6),"",$V6*MAX(0,MIN($J6,15)-MAX($I6,0))/($J6-$I6)) -> 0.10709232 | X6: =IF(OR($V6="",$I6="",$J6="",$J6<=$I6),"",$V6*MAX(0,MIN($J6,30)-MAX($I6,15))/($J6-$I6)) -> 0 | Y6: =IF(OR($V6="",$I6="",$J6="",$J6<=$I6),"",$V6*MAX(0,MIN($J6,50)-MAX($I6,30))/($J6-$I6)) -> 0 | Z6: =IF(OR($V6="",$I6="",$J6="",$J6<=$I6),"",$V6*MAX(0,MIN($J6,100)-MAX($I6,50))/($J6-$I6)) -> 0 | AA6: =IF($A6="","",IF(OR($C6="",$D6="",$D6<=$C6),"CHECK: depths missing, or bottom not below top",IF(COUNTIFS($A$6:$A$205,$A6,$C$6:$C$205,$C6)>1,"DUPLICATE slice",IF(COUNTIFS($A$6:$A$205,$A6,$C$6:$C$205,"<"&$D6,$D$6:$D$205,">"&$C6)>1,"OVERLAP with another slice",IF(AND($C6>0,COUNTIFS($A$6:$A$205,$A6,$D$6:$D$205,$C6)=0),"GAP above this slice",IF(OR($G6="",$H6=""),"CHECK: Core ID not in Core Log, or its compaction / diameter missing",IF(AND(IF(COUNTIFS('2. Plot & Core Log'!$B$6:$B$35,$A6,'2. Plot & Core Log'!$L$6:$L$35,">0")=0,"",SUMIFS('2. Plot & Core Log'!$L$6:$L$35,'2. Plot & Core Log'!$B$6:$B$35,$A6))<>"",$D6>IF(COUNTIFS('2. Plot & Core Log'!$B$6:$B$35,$A6,'2. Plot & Core Log'!$L$6:$L$35,">0")=0,"",SUMIFS('2. Plot & Core Log'!$L$6:$L$35,'2. Plot & Core Log'!$B$6:$B$35,$A6))),"CHECK: slice deeper than the core length on Sheet 2",IF(OR($M6="",$N6="",$O6=""),"AWAITING LAB (dry weight, carbon value or type)",IF(AND(UPPER($O6)<>"OC",UPPER($O6)<>"LOI"),IF(UPPER($O6)="TC","TC is not organic carbon — ask the lab for OC or IC","CHECK: type must be OC, TC or LOI"),IF($R6="",IF(AND(LOI_INTERCEPT<>"",LOI_SLOPE<>""),"CHECK: LOI below the range of the conversion equation (OC would be < 0)","CHECK: LOI conversion not set (Instructions tab)"),IF(OR($Q6<=0,$Q6>2.65,$R6>50),"CHECK: bulk density outside 0–2.65 g/cm3 or OC > 50%","OK"))))))))))) -> OK
A7: COW-S5 | B7: 2 | C7: 1 | D7: 2 | E7: LOI 550 °C, 5 h (no elemental C for this slice). Dry weight back-calculated from published bulk density. | F7: =IF(OR($C7="",$D7=""),"",$D7-$C7) -> 1 | G7: =IF($A7="","",IFERROR(INDEX('2. Plot & Core Log'!$M$6:$M$35,MATCH($A7,'2. Plot & Core Log'!$B$6:$B$35,0)),"")) -> 1 | H7: =IF($A7="","",IFERROR(INDEX('2. Plot & Core Log'!$S$6:$S$35,MATCH($A7,'2. Plot & Core Log'!$B$6:$B$35,0)),"")) -> 7.6 | I7: =IF(OR($C7="",$G7=""),"",$C7*$G7) -> 1 | J7: =IF(OR($D7="",$G7=""),"",$D7*$G7) -> 2 | K7: =IF(OR($F7="",$H7=""),"",PI()*(($H7/2)^2)*$F7) -> 45.364598 | M7: 69.86 | N7: 3 | O7: LOI | P7: =IF(OR($L7="",$M7="",$L7=0),"",(($L7-$M7)/$L7)*100) | Q7: =IF(OR($M7="",$K7="",$K7=0),"",$M7/$K7) -> 1.5399674 | R7: =IF(OR($N7="",$O7=""),"",IF(UPPER($O7)="OC",$N7,IF(UPPER($O7)="LOI",IF(OR(LOI_INTERCEPT="",LOI_SLOPE=""),"",IF(LOI_INTERCEPT+LOI_SLOPE*$N7<0,"",LOI_INTERCEPT+LOI_SLOPE*$N7)),""))) -> 0.763 | S7: =IF($R7="","",$R7*10) -> 7.63 | T7: =IF(OR($Q7="",$R7=""),"",$Q7*$R7/100) -> 0.011749951 | U7: =IF(OR($T7="",$F7=""),"",$T7*$F7) -> 0.011749951 | V7: =IF($U7="","",$U7*10) -> 0.11749951 | W7: =IF(OR($V7="",$I7="",$J7="",$J7<=$I7),"",$V7*MAX(0,MIN($J7,15)-MAX($I7,0))/($J7-$I7)) -> 0.11749951 | X7: =IF(OR($V7="",$I7="",$J7="",$J7<=$I7),"",$V7*MAX(0,MIN($J7,30)-MAX($I7,15))/($J7-$I7)) -> 0 | Y7: =IF(OR($V7="",$I7="",$J7="",$J7<=$I7),"",$V7*MAX(0,MIN($J7,50)-MAX($I7,30))/($J7-$I7)) -> 0 | Z7: =IF(OR($V7="",$I7="",$J7="",$J7<=$I7),"",$V7*MAX(0,MIN($J7,100)-MAX($I7,50))/($J7-$I7)) -> 0 | AA7: =IF($A7="","",IF(OR($C7="",$D7="",$D7<=$C7),"CHECK: depths missing, or bottom not below top",IF(COUNTIFS($A$6:$A$205,$A7,$C$6:$C$205,$C7)>1,"DUPLICATE slice",IF(COUNTIFS($A$6:$A$205,$A7,$C$6:$C$205,"<"&$D7,$D$6:$D$205,">"&$C7)>1,"OVERLAP with another slice",IF(AND($C7>0,COUNTIFS($A$6:$A$205,$A7,$D$6:$D$205,$C7)=0),"GAP above this slice",IF(OR($G7="",$H7=""),"CHECK: Core ID not in Core Log, or its compaction / diameter missing",IF(AND(IF(COUNTIFS('2. Plot & Core Log'!$B$6:$B$35,$A7,'2. Plot & Core Log'!$L$6:$L$35,">0")=0,"",SUMIFS('2. Plot & Core Log'!$L$6:$L$35,'2. Plot & Core Log'!$B$6:$B$35,$A7))<>"",$D7>IF(COUNTIFS('2. Plot & Core Log'!$B$6:$B$35,$A7,'2. Plot & Core Log'!$L$6:$L$35,">0")=0,"",SUMIFS('2. Plot & Core Log'!$L$6:$L$35,'2. Plot & Core Log'!$B$6:$B$35,$A7))),"CHECK: slice deeper than the core length on Sheet 2",IF(OR($M7="",$N7="",$O7=""),"AWAITING LAB (dry weight, carbon value or type)",IF(AND(UPPER($O7)<>"OC",UPPER($O7)<>"LOI"),IF(UPPER($O7)="TC","TC is not organic carbon — ask the lab for OC or IC","CHECK: type must be OC, TC or LOI"),IF($R7="",IF(AND(LOI_INTERCEPT<>"",LOI_SLOPE<>""),"CHECK: LOI below the range of the conversion equation (OC would be < 0)","CHECK: LOI conversion not set (Instructions tab)"),IF(OR($Q7<=0,$Q7>2.65,$R7>50),"CHECK: bulk density outside 0–2.65 g/cm3 or OC > 50%","OK"))))))))))) -> OK
A8: COW-S5 | B8: 3 | C8: 2 | D8: 3 | E8: LOI 550 °C, 5 h (no elemental C for this slice). Dry weight back-calculated from published bulk density. | F8: =IF(OR($C8="",$D8=""),"",$D8-$C8) -> 1 | G8: =IF($A8="","",IFERROR(INDEX('2. Plot & Core Log'!$M$6:$M$35,MATCH($A8,'2. Plot & Core Log'!$B$6:$B$35,0)),"")) -> 1 | H8: =IF($A8="","",IFERROR(INDEX('2. Plot & Core Log'!$S$6:$S$35,MATCH($A8,'2. Plot & Core Log'!$B$6:$B$35,0)),"")) -> 7.6 | I8: =IF(OR($C8="",$G8=""),"",$C8*$G8) -> 2 | J8: =IF(OR($D8="",$G8=""),"",$D8*$G8) -> 3 | K8: =IF(OR($F8="",$H8=""),"",PI()*(($H8/2)^2)*$F8) -> 45.364598 | M8: 75.76 | N8: 2.9 | O8: LOI | P8: =IF(OR($L8="",$M8="",$L8=0),"",(($L8-$M8)/$L8)*100) | Q8: =IF(OR($M8="",$K8="",$K8=0),"",$M8/$K8) -> 1.6700247 | R8: =IF(OR($N8="",$O8=""),"",IF(UPPER($O8)="OC",$N8,IF(UPPER($O8)="LOI",IF(OR(LOI_INTERCEPT="",LOI_SLOPE=""),"",IF(LOI_INTERCEPT+LOI_SLOPE*$N8<0,"",LOI_INTERCEPT+LOI_SLOPE*$N8)),""))) -> 0.731 | S8: =IF($R8="","",$R8*10) -> 7.31 | T8: =IF(OR($Q8="",$R8=""),"",$Q8*$R8/100) -> 0.012207881 | U8: =IF(OR($T8="",$F8=""),"",$T8*$F8) -> 0.012207881 | V8: =IF($U8="","",$U8*10) -> 0.12207881 | W8: =IF(OR($V8="",$I8="",$J8="",$J8<=$I8),"",$V8*MAX(0,MIN($J8,15)-MAX($I8,0))/($J8-$I8)) -> 0.12207881 | X8: =IF(OR($V8="",$I8="",$J8="",$J8<=$I8),"",$V8*MAX(0,MIN($J8,30)-MAX($I8,15))/($J8-$I8)) -> 0 | Y8: =IF(OR($V8="",$I8="",$J8="",$J8<=$I8),"",$V8*MAX(0,MIN($J8,50)-MAX($I8,30))/($J8-$I8)) -> 0 | Z8: =IF(OR($V8="",$I8="",$J8="",$J8<=$I8),"",$V8*MAX(0,MIN($J8,100)-MAX($I8,50))/($J8-$I8)) -> 0 | AA8: =IF($A8="","",IF(OR($C8="",$D8="",$D8<=$C8),"CHECK: depths missing, or bottom not below top",IF(COUNTIFS($A$6:$A$205,$A8,$C$6:$C$205,$C8)>1,"DUPLICATE slice",IF(COUNTIFS($A$6:$A$205,$A8,$C$6:$C$205,"<"&$D8,$D$6:$D$205,">"&$C8)>1,"OVERLAP with another slice",IF(AND($C8>0,COUNTIFS($A$6:$A$205,$A8,$D$6:$D$205,$C8)=0),"GAP above this slice",IF(OR($G8="",$H8=""),"CHECK: Core ID not in Core Log, or its compaction / diameter missing",IF(AND(IF(COUNTIFS('2. Plot & Core Log'!$B$6:$B$35,$A8,'2. Plot & Core Log'!$L$6:$L$35,">0")=0,"",SUMIFS('2. Plot & Core Log'!$L$6:$L$35,'2. Plot & Core Log'!$B$6:$B$35,$A8))<>"",$D8>IF(COUNTIFS('2. Plot & Core Log'!$B$6:$B$35,$A8,'2. Plot & Core Log'!$L$6:$L$35,">0")=0,"",SUMIFS('2. Plot & Core Log'!$L$6:$L$35,'2. Plot & Core Log'!$B$6:$B$35,$A8))),"CHECK: slice deeper than the core length on Sheet 2",IF(OR($M8="",$N8="",$O8=""),"AWAITING LAB (dry weight, carbon value or type)",IF(AND(UPPER($O8)<>"OC",UPPER($O8)<>"LOI"),IF(UPPER($O8)="TC","TC is not organic carbon — ask the lab for OC or IC","CHECK: type must be OC, TC or LOI"),IF($R8="",IF(AND(LOI_INTERCEPT<>"",LOI_SLOPE<>""),"CHECK: LOI below the range of the conversion equation (OC would be < 0)","CHECK: LOI conversion not set (Instructions tab)"),IF(OR($Q8<=0,$Q8>2.65,$R8>50),"CHECK: bulk density outside 0–2.65 g/cm3 or OC > 50%","OK"))))))))))) -> OK
A9: COW-S5 | B9: 4 | C9: 3 | D9: 4 | E9: LOI 550 °C, 5 h (no elemental C for this slice). Dry weight back-calculated from published bulk density. | F9: =IF(OR($C9="",$D9=""),"",$D9-$C9) -> 1 | G9: =IF($A9="","",IFERROR(INDEX('2. Plot & Core Log'!$M$6:$M$35,MATCH($A9,'2. Plot & Core Log'!$B$6:$B$35,0)),"")) -> 1 | H9: =IF($A9="","",IFERROR(INDEX('2. Plot & Core Log'!$S$6:$S$35,MATCH($A9,'2. Plot & Core Log'!$B$6:$B$35,0)),"")) -> 7.6 | I9: =IF(OR($C9="",$G9=""),"",$C9*$G9) -> 3 | J9: =IF(OR($D9="",$G9=""),"",$D9*$G9) -> 4 | K9: =IF(OR($F9="",$H9=""),"",PI()*(($H9/2)^2)*$F9) -> 45.364598 | M9: 74.4 | N9: 2.8 | O9: LOI | P9: =IF(OR($L9="",$M9="",$L9=0),"",(($L9-$M9)/$L9)*100) | Q9: =IF(OR($M9="",$K9="",$K9=0),"",$M9/$K9) -> 1.6400454 | R9: =IF(OR($N9="",$O9=""),"",IF(UPPER($O9)="OC",$N9,IF(UPPER($O9)="LOI",IF(OR(LOI_INTERCEPT="",LOI_SLOPE=""),"",IF(LOI_INTERCEPT+LOI_SLOPE*$N9<0,"",LOI_INTERCEPT+LOI_SLOPE*$N9)),""))) -> 0.699 | S9: =IF($R9="","",$R9*10) -> 6.99 | T9: =IF(OR($Q9="",$R9=""),"",$Q9*$R9/100) -> 0.011463917 | U9: =IF(OR($T9="",$F9=""),"",$T9*$F9) -> 0.011463917 | V9: =IF($U9="","",$U9*10) -> 0.11463917 | W9: =IF(OR($V9="",$I9="",$J9="",$J9<=$I9),"",$V9*MAX(0,MIN($J9,15)-MAX($I9,0))/($J9-$I9)) -> 0.11463917 | X9: =IF(OR($V9="",$I9="",$J9="",$J9<=$I9),"",$V9*MAX(0,MIN($J9,30)-MAX($I9,15))/($J9-$I9)) -> 0 | Y9: =IF(OR($V9="",$I9="",$J9="",$J9<=$I9),"",$V9*MAX(0,MIN($J9,50)-MAX($I9,30))/($J9-$I9)) -> 0 | Z9: =IF(OR($V9="",$I9="",$J9="",$J9<=$I9),"",$V9*MAX(0,MIN($J9,100)-MAX($I9,50))/($J9-$I9)) -> 0 | AA9: =IF($A9="","",IF(OR($C9="",$D9="",$D9<=$C9),"CHECK: depths missing, or bottom not below top",IF(COUNTIFS($A$6:$A$205,$A9,$C$6:$C$205,$C9)>1,"DUPLICATE slice",IF(COUNTIFS($A$6:$A$205,$A9,$C$6:$C$205,"<"&$D9,$D$6:$D$205,">"&$C9)>1,"OVERLAP with another slice",IF(AND($C9>0,COUNTIFS($A$6:$A$205,$A9,$D$6:$D$205,$C9)=0),"GAP above this slice",IF(OR($G9="",$H9=""),"CHECK: Core ID not in Core Log, or its compaction / diameter missing",IF(AND(IF(COUNTIFS('2. Plot & Core Log'!$B$6:$B$35,$A9,'2. Plot & Core Log'!$L$6:$L$35,">0")=0,"",SUMIFS('2. Plot & Core Log'!$L$6:$L$35,'2. Plot & Core Log'!$B$6:$B$35,$A9))<>"",$D9>IF(COUNTIFS('2. Plot & Core Log'!$B$6:$B$35,$A9,'2. Plot & Core Log'!$L$6:$L$35,">0")=0,"",SUMIFS('2. Plot & Core Log'!$L$6:$L$35,'2. Plot & Core Log'!$B$6:$B$35,$A9))),"CHECK: slice deeper than the core length on Sheet 2",IF(OR($M9="",$N9="",$O9=""),"AWAITING LAB (dry weight, carbon value or type)",IF(AND(UPPER($O9)<>"OC",UPPER($O9)<>"LOI"),IF(UPPER($O9)="TC","TC is not organic carbon — ask the lab for OC or IC","CHECK: type must be OC, TC or LOI"),IF($R9="",IF(AND(LOI_INTERCEPT<>"",LOI_SLOPE<>""),"CHECK: LOI below the range of the conversion equation (OC would be < 0)","CHECK: LOI conversion not set (Instructions tab)"),IF(OR($Q9<=0,$Q9>2.65,$R9>50),"CHECK: bulk density outside 0–2.65 g/cm3 or OC > 50%","OK"))))))))))) -> OK
A10: COW-S5 | B10: 5 | C10: 4 | D10: 5 | E10: LOI 550 °C, 5 h (no elemental C for this slice). Dry weight back-calculated from published bulk density. | F10: =IF(OR($C10="",$D10=""),"",$D10-$C10) -> 1 | G10: =IF($A10="","",IFERROR(INDEX('2. Plot & Core Log'!$M$6:$M$35,MATCH($A10,'2. Plot & Core Log'!$B$6:$B$35,0)),"")) -> 1 | H10: =IF($A10="","",IFERROR(INDEX('2. Plot & Core Log'!$S$6:$S$35,MATCH($A10,'2. Plot & Core Log'!$B$6:$B$35,0)),"")) -> 7.6 | I10: =IF(OR($C10="",$G10=""),"",$C10*$G10) -> 4 | J10: =IF(OR($D10="",$G10=""),"",$D10*$G10) -> 5 | K10: =IF(OR($F10="",$H10=""),"",PI()*(($H10/2)^2)*$F10) -> 45.364598 | M10: 69.86 | N10: 2.9 | O10: LOI | P10: =IF(OR($L10="",$M10="",$L10=0),"",(($L10-$M10)/$L10)*100) | Q10: =IF(OR($M10="",$K10="",$K10=0),"",$M10/$K10) -> 1.5399674 | R10: =IF(OR($N10="",$O10=""),"",IF(UPPER($O10)="OC",$N10,IF(UPPER($O10)="LOI",IF(OR(LOI_INTERCEPT="",LOI_SLOPE=""),"",IF(LOI_INTERCEPT+LOI_SLOPE*$N10<0,"",LOI_INTERCEPT+LOI_SLOPE*$N10)),""))) -> 0.731 | S10: =IF($R10="","",$R10*10) -> 7.31 | T10: =IF(OR($Q10="",$R10=""),"",$Q10*$R10/100) -> 0.011257161 | U10: =IF(OR($T10="",$F10=""),"",$T10*$F10) -> 0.011257161 | V10: =IF($U10="","",$U10*10) -> 0.11257161 | W10: =IF(OR($V10="",$I10="",$J10="",$J10<=$I10),"",$V10*MAX(0,MIN($J10,15)-MAX($I10,0))/($J10-$I10)) -> 0.11257161 | X10: =IF(OR($V10="",$I10="",$J10="",$J10<=$I10),"",$V10*MAX(0,MIN($J10,30)-MAX($I10,15))/($J10-$I10)) -> 0 | Y10: =IF(OR($V10="",$I10="",$J10="",$J10<=$I10),"",$V10*MAX(0,MIN($J10,50)-MAX($I10,30))/($J10-$I10)) -> 0 | Z10: =IF(OR($V10="",$I10="",$J10="",$J10<=$I10),"",$V10*MAX(0,MIN($J10,100)-MAX($I10,50))/($J10-$I10)) -> 0 | AA10: =IF($A10="","",IF(OR($C10="",$D10="",$D10<=$C10),"CHECK: depths missing, or bottom not below top",IF(COUNTIFS($A$6:$A$205,$A10,$C$6:$C$205,$C10)>1,"DUPLICATE slice",IF(COUNTIFS($A$6:$A$205,$A10,$C$6:$C$205,"<"&$D10,$D$6:$D$205,">"&$C10)>1,"OVERLAP with another slice",IF(AND($C10>0,COUNTIFS($A$6:$A$205,$A10,$D$6:$D$205,$C10)=0),"GAP above this slice",IF(OR($G10="",$H10=""),"CHECK: Core ID not in Core Log, or its compaction / diameter missing",IF(AND(IF(COUNTIFS('2. Plot & Core Log'!$B$6:$B$35,$A10,'2. Plot & Core Log'!$L$6:$L$35,">0")=0,"",SUMIFS('2. Plot & Core Log'!$L$6:$L$35,'2. Plot & Core Log'!$B$6:$B$35,$A10))<>"",$D10>IF(COUNTIFS('2. Plot & Core Log'!$B$6:$B$35,$A10,'2. Plot & Core Log'!$L$6:$L$35,">0")=0,"",SUMIFS('2. Plot & Core Log'!$L$6:$L$35,'2. Plot & Core Log'!$B$6:$B$35,$A10))),"CHECK: slice deeper than the core length on Sheet 2",IF(OR($M10="",$N10="",$O10=""),"AWAITING LAB (dry weight, carbon value or type)",IF(AND(UPPER($O10)<>"OC",UPPER($O10)<>"LOI"),IF(UPPER($O10)="TC","TC is not organic carbon — ask the lab for OC or IC","CHECK: type must be OC, TC or LOI"),IF($R10="",IF(AND(LOI_INTERCEPT<>"",LOI_SLOPE<>""),"CHECK: LOI below the range of the conversion equation (OC would be < 0)","CHECK: LOI conversion not set (Instructions tab)"),IF(OR($Q10<=0,$Q10>2.65,$R10>50),"CHECK: bulk density outside 0–2.65 g/cm3 or OC > 50%","OK"))))))))))) -> OK
A11: COW-S5 | B11: 6 | C11: 5 | D11: 6 | E11: LOI 550 °C, 5 h (no elemental C for this slice). Dry weight back-calculated from published bulk density. | F11: =IF(OR($C11="",$D11=""),"",$D11-$C11) -> 1 | G11: =IF($A11="","",IFERROR(INDEX('2. Plot & Core Log'!$M$6:$M$35,MATCH($A11,'2. Plot & Core Log'!$B$6:$B$35,0)),"")) -> 1 | H11: =IF($A11="","",IFERROR(INDEX('2. Plot & Core Log'!$S$6:$S$35,MATCH($A11,'2. Plot & Core Log'!$B$6:$B$35,0)),"")) -> 7.6 | I11: =IF(OR($C11="",$G11=""),"",$C11*$G11) -> 5 | J11: =IF(OR($D11="",$G11=""),"",$D11*$G11) -> 6 | K11: =IF(OR($F11="",$H11=""),"",PI()*(($H11/2)^2)*$F11) -> 45.364598 | M11: 73.04 | N11: 3.3 | O11: LOI | P11: =IF(OR($L11="",$M11="",$L11=0),"",(($L11-$M11)/$L11)*100) | Q11: =IF(OR($M11="",$K11="",$K11=0),"",$M11/$K11) -> 1.6100661 | R11: =IF(OR($N11="",$O11=""),"",IF(UPPER($O11)="OC",$N11,IF(UPPER($O11)="LOI",IF(OR(LOI_INTERCEPT="",LOI_SLOPE=""),"",IF(LOI_INTERCEPT+LOI_SLOPE*$N11<0,"",LOI_INTERCEPT+LOI_SLOPE*$N11)),""))) -> 0.859 | S11: =IF($R11="","",$R11*10) -> 8.59 | T11: =IF(OR($Q11="",$R11=""),"",$Q11*$R11/100) -> 0.013830468 | U11: =IF(OR($T11="",$F11=""),"",$T11*$F11) -> 0.013830468 | V11: =IF($U11="","",$U11*10) -> 0.13830468 | W11: =IF(OR($V11="",$I11="",$J11="",$J11<=$I11),"",$V11*MAX(0,MIN($J11,15)-MAX($I11,0))/($J11-$I11)) -> 0.13830468 | X11: =IF(OR($V11="",$I11="",$J11="",$J11<=$I11),"",$V11*MAX(0,MIN($J11,30)-MAX($I11,15))/($J11-$I11)) -> 0 | Y11: =IF(OR($V11="",$I11="",$J11="",$J11<=$I11),"",$V11*MAX(0,MIN($J11,50)-MAX($I11,30))/($J11-$I11)) -> 0 | Z11: =IF(OR($V11="",$I11="",$J11="",$J11<=$I11),"",$V11*MAX(0,MIN($J11,100)-MAX($I11,50))/($J11-$I11)) -> 0 | AA11: =IF($A11="","",IF(OR($C11="",$D11="",$D11<=$C11),"CHECK: depths missing, or bottom not below top",IF(COUNTIFS($A$6:$A$205,$A11,$C$6:$C$205,$C11)>1,"DUPLICATE slice",IF(COUNTIFS($A$6:$A$205,$A11,$C$6:$C$205,"<"&$D11,$D$6:$D$205,">"&$C11)>1,"OVERLAP with another slice",IF(AND($C11>0,COUNTIFS($A$6:$A$205,$A11,$D$6:$D$205,$C11)=0),"GAP above this slice",IF(OR($G11="",$H11=""),"CHECK: Core ID not in Core Log, or its compaction / diameter missing",IF(AND(IF(COUNTIFS('2. Plot & Core Log'!$B$6:$B$35,$A11,'2. Plot & Core Log'!$L$6:$L$35,">0")=0,"",SUMIFS('2. Plot & Core Log'!$L$6:$L$35,'2. Plot & Core Log'!$B$6:$B$35,$A11))<>"",$D11>IF(COUNTIFS('2. Plot & Core Log'!$B$6:$B$35,$A11,'2. Plot & Core Log'!$L$6:$L$35,">0")=0,"",SUMIFS('2. Plot & Core Log'!$L$6:$L$35,'2. Plot & Core Log'!$B$6:$B$35,$A11))),"CHECK: slice deeper than the core length on Sheet 2",IF(OR($M11="",$N11="",$O11=""),"AWAITING LAB (dry weight, carbon value or type)",IF(AND(UPPER($O11)<>"OC",UPPER($O11)<>"LOI"),IF(UPPER($O11)="TC","TC is not organic carbon — ask the lab for OC or IC","CHECK: type must be OC, TC or LOI"),IF($R11="",IF(AND(LOI_INTERCEPT<>"",LOI_SLOPE<>""),"CHECK: LOI below the range of the conversion equation (OC would be < 0)","CHECK: LOI conversion not set (Instructions tab)"),IF(OR($Q11<=0,$Q11>2.65,$R11>50),"CHECK: bulk density outside 0–2.65 g/cm3 or OC > 50%","OK"))))))))))) -> OK
A12: COW-S5 | B12: 7 | C12: 6 | D12: 7 | E12: LOI 550 °C, 5 h (no elemental C for this slice). Dry weight back-calculated from published bulk density. | F12: =IF(OR($C12="",$D12=""),"",$D12-$C12) -> 1 | G12: =IF($A12="","",IFERROR(INDEX('2. Plot & Core Log'!$M$6:$M$35,MATCH($A12,'2. Plot & Core Log'!$B$6:$B$35,0)),"")) -> 1 | H12: =IF($A12="","",IFERROR(INDEX('2. Plot & Core Log'!$S$6:$S$35,MATCH($A12,'2. Plot & Core Log'!$B$6:$B$35,0)),"")) -> 7.6 | I12: =IF(OR($C12="",$G12=""),"",$C12*$G12) -> 6 | J12: =IF(OR($D12="",$G12=""),"",$D12*$G12) -> 7 | K12: =IF(OR($F12="",$H12=""),"",PI()*(($H12/2)^2)*$F12) -> 45.364598 | M12: 69.86 | N12: 2.2 | O12: LOI | P12: =IF(OR($L12="",$M12="",$L12=0),"",(($L12-$M12)/$L12)*100) | Q12: =IF(OR($M12="",$K12="",$K12=0),"",$M12/$K12) -> 1.5399674 | R12: =IF(OR($N12="",$O12=""),"",IF(UPPER($O12)="OC",$N12,IF(UPPER($O12)="LOI",IF(OR(LOI_INTERCEPT="",LOI_SLOPE=""),"",IF(LOI_INTERCEPT+LOI_SLOPE*$N12<0,"",LOI_INTERCEPT+LOI_SLOPE*$N12)),""))) -> 0.507 | S12: =IF($R12="","",$R12*10) -> 5.07 | T12: =IF(OR($Q12="",$R12=""),"",$Q12*$R12/100) -> 0.0078076345 | U12: =IF(OR($T12="",$F12=""),"",$T12*$F12) -> 0.0078076345 | V12: =IF($U12="","",$U12*10) -> 0.078076345 | W12: =IF(OR($V12="",$I12="",$J12="",$J12<=$I12),"",$V12*MAX(0,MIN($J12,15)-MAX($I12,0))/($J12-$I12)) -> 0.078076345 | X12: =IF(OR($V12="",$I12="",$J12="",$J12<=$I12),"",$V12*MAX(0,MIN($J12,30)-MAX($I12,15))/($J12-$I12)) -> 0 | Y12: =IF(OR($V12="",$I12="",$J12="",$J12<=$I12),"",$V12*MAX(0,MIN($J12,50)-MAX($I12,30))/($J12-$I12)) -> 0 | Z12: =IF(OR($V12="",$I12="",$J12="",$J12<=$I12),"",$V12*MAX(0,MIN($J12,100)-MAX($I12,50))/($J12-$I12)) -> 0 | AA12: =IF($A12="","",IF(OR($C12="",$D12="",$D12<=$C12),"CHECK: depths missing, or bottom not below top",IF(COUNTIFS($A$6:$A$205,$A12,$C$6:$C$205,$C12)>1,"DUPLICATE slice",IF(COUNTIFS($A$6:$A$205,$A12,$C$6:$C$205,"<"&$D12,$D$6:$D$205,">"&$C12)>1,"OVERLAP with another slice",IF(AND($C12>0,COUNTIFS($A$6:$A$205,$A12,$D$6:$D$205,$C12)=0),"GAP above this slice",IF(OR($G12="",$H12=""),"CHECK: Core ID not in Core Log, or its compaction / diameter missing",IF(AND(IF(COUNTIFS('2. Plot & Core Log'!$B$6:$B$35,$A12,'2. Plot & Core Log'!$L$6:$L$35,">0")=0,"",SUMIFS('2. Plot & Core Log'!$L$6:$L$35,'2. Plot & Core Log'!$B$6:$B$35,$A12))<>"",$D12>IF(COUNTIFS('2. Plot & Core Log'!$B$6:$B$35,$A12,'2. Plot & Core Log'!$L$6:$L$35,">0")=0,"",SUMIFS('2. Plot & Core Log'!$L$6:$L$35,'2. Plot & Core Log'!$B$6:$B$35,$A12))),"CHECK: slice deeper than the core length on Sheet 2",IF(OR($M12="",$N12="",$O12=""),"AWAITING LAB (dry weight, carbon value or type)",IF(AND(UPPER($O12)<>"OC",UPPER($O12)<>"LOI"),IF(UPPER($O12)="TC","TC is not organic carbon — ask the lab for OC or IC","CHECK: type must be OC, TC or LOI"),IF($R12="",IF(AND(LOI_INTERCEPT<>"",LOI_SLOPE<>""),"CHECK: LOI below the range of the conversion equation (OC would be < 0)","CHECK: LOI conversion not set (Instructions tab)"),IF(OR($Q12<=0,$Q12>2.65,$R12>50),"CHECK: bulk density outside 0–2.65 g/cm3 or OC > 50%","OK"))))))))))) -> OK
A13: COW-S5 | B13: 8 | C13: 7 | D13: 8 | E13: LOI 550 °C, 5 h (no elemental C for this slice). Dry weight back-calculated from published bulk density. | F13: =IF(OR($C13="",$D13=""),"",$D13-$C13) -> 1 | G13: =IF($A13="","",IFERROR(INDEX('2. Plot & Core Log'!$M$6:$M$35,MATCH($A13,'2. Plot & Core Log'!$B$6:$B$35,0)),"")) -> 1 | H13: =IF($A13="","",IFERROR(INDEX('2. Plot & Core Log'!$S$6:$S$35,MATCH($A13,'2. Plot & Core Log'!$B$6:$B$35,0)),"")) -> 7.6 | I13: =IF(OR($C13="",$G13=""),"",$C13*$G13) -> 7 | J13: =IF(OR($D13="",$G13=""),"",$D13*$G13) -> 8 | K13: =IF(OR($F13="",$H13=""),"",PI()*(($H13/2)^2)*$F13) -> 45.364598 | M13: 82.56 | N13: 3.2 | O13: LOI | P13: =IF(OR($L13="",$M13="",$L13=0),"",(($L13-$M13)/$L13)*100) | Q13: =IF(OR($M13="",$K13="",$K13=0),"",$M13/$K13) -> 1.8199213 | R13: =IF(OR($N13="",$O13=""),"",IF(UPPER($O13)="OC",$N13,IF(UPPER($O13)="LOI",IF(OR(LOI_INTERCEPT="",LOI_SLOPE=""),"",IF(LOI_INTERCEPT+LOI_SLOPE*$N13<0,"",LOI_INTERCEPT+LOI_SLOPE*$N13)),""))) -> 0.827 | S13: =IF($R13="","",$R13*10) -> 8.27 | T13: =IF(OR($Q13="",$R13=""),"",$Q13*$R13/100) -> 0.01505075 | U13: =IF(OR($T13="",$F13=""),"",$T13*$F13) -> 0.01505075 | V13: =IF($U13="","",$U13*10) -> 0.1505075 | W13: =IF(OR($V13="",$I13="",$J13="",$J13<=$I13),"",$V13*MAX(0,MIN($J13,15)-MAX($I13,0))/($J13-$I13)) -> 0.1505075 | X13: =IF(OR($V13="",$I13="",$J13="",$J13<=$I13),"",$V13*MAX(0,MIN($J13,30)-MAX($I13,15))/($J13-$I13)) -> 0 | Y13: =IF(OR($V13="",$I13="",$J13="",$J13<=$I13),"",$V13*MAX(0,MIN($J13,50)-MAX($I13,30))/($J13-$I13)) -> 0 | Z13: =IF(OR($V13="",$I13="",$J13="",$J13<=$I13),"",$V13*MAX(0,MIN($J13,100)-MAX($I13,50))/($J13-$I13)) -> 0 | AA13: =IF($A13="","",IF(OR($C13="",$D13="",$D13<=$C13),"CHECK: depths missing, or bottom not below top",IF(COUNTIFS($A$6:$A$205,$A13,$C$6:$C$205,$C13)>1,"DUPLICATE slice",IF(COUNTIFS($A$6:$A$205,$A13,$C$6:$C$205,"<"&$D13,$D$6:$D$205,">"&$C13)>1,"OVERLAP with another slice",IF(AND($C13>0,COUNTIFS($A$6:$A$205,$A13,$D$6:$D$205,$C13)=0),"GAP above this slice",IF(OR($G13="",$H13=""),"CHECK: Core ID not in Core Log, or its compaction / diameter missing",IF(AND(IF(COUNTIFS('2. Plot & Core Log'!$B$6:$B$35,$A13,'2. Plot & Core Log'!$L$6:$L$35,">0")=0,"",SUMIFS('2. Plot & Core Log'!$L$6:$L$35,'2. Plot & Core Log'!$B$6:$B$35,$A13))<>"",$D13>IF(COUNTIFS('2. Plot & Core Log'!$B$6:$B$35,$A13,'2. Plot & Core Log'!$L$6:$L$35,">0")=0,"",SUMIFS('2. Plot & Core Log'!$L$6:$L$35,'2. Plot & Core Log'!$B$6:$B$35,$A13))),"CHECK: slice deeper than the core length on Sheet 2",IF(OR($M13="",$N13="",$O13=""),"AWAITING LAB (dry weight, carbon value or type)",IF(AND(UPPER($O13)<>"OC",UPPER($O13)<>"LOI"),IF(UPPER($O13)="TC","TC is not organic carbon — ask the lab for OC or IC","CHECK: type must be OC, TC or LOI"),IF($R13="",IF(AND(LOI_INTERCEPT<>"",LOI_SLOPE<>""),"CHECK: LOI below the range of the conversion equation (OC would be < 0)","CHECK: LOI conversion not set (Instructions tab)"),IF(OR($Q13<=0,$Q13>2.65,$R13>50),"CHECK: bulk density outside 0–2.65 g/cm3 or OC > 50%","OK"))))))))))) -> OK
A14: COW-S5 | B14: 9 | C14: 8 | D14: 9 | E14: LOI 550 °C, 5 h (no elemental C for this slice). Dry weight back-calculated from published bulk density. | F14: =IF(OR($C14="",$D14=""),"",$D14-$C14) -> 1 | G14: =IF($A14="","",IFERROR(INDEX('2. Plot & Core Log'!$M$6:$M$35,MATCH($A14,'2. Plot & Core Log'!$B$6:$B$35,0)),"")) -> 1 | H14: =IF($A14="","",IFERROR(INDEX('2. Plot & Core Log'!$S$6:$S$35,MATCH($A14,'2. Plot & Core Log'!$B$6:$B$35,0)),"")) -> 7.6 | I14: =IF(OR($C14="",$G14=""),"",$C14*$G14) -> 8 | J14: =IF(OR($D14="",$G14=""),"",$D14*$G14) -> 9 | K14: =IF(OR($F14="",$H14=""),"",PI()*(($H14/2)^2)*$F14) -> 45.364598 | M14: 84.38 | N14: 2.8 | O14: LOI | P14: =IF(OR($L14="",$M14="",$L14=0),"",(($L14-$M14)/$L14)*100) | Q14: =IF(OR($M14="",$K14="",$K14=0),"",$M14/$K14) -> 1.8600407 | R14: =IF(OR($N14="",$O14=""),"",IF(UPPER($O14)="OC",$N14,IF(UPPER($O14)="LOI",IF(OR(LOI_INTERCEPT="",LOI_SLOPE=""),"",IF(LOI_INTERCEPT+LOI_SLOPE*$N14<0,"",LOI_INTERCEPT+LOI_SLOPE*$N14)),""))) -> 0.699 | S14: =IF($R14="","",$R14*10) -> 6.99 | T14: =IF(OR($Q14="",$R14=""),"",$Q14*$R14/100) -> 0.013001685 | U14: =IF(OR($T14="",$F14=""),"",$T14*$F14) -> 0.013001685 | V14: =IF($U14="","",$U14*10) -> 0.13001685 | W14: =IF(OR($V14="",$I14="",$J14="",$J14<=$I14),"",$V14*MAX(0,MIN($J14,15)-MAX($I14,0))/($J14-$I14)) -> 0.13001685 | X14: =IF(OR($V14="",$I14="",$J14="",$J14<=$I14),"",$V14*MAX(0,MIN($J14,30)-MAX($I14,15))/($J14-$I14)) -> 0 | Y14: =IF(OR($V14="",$I14="",$J14="",$J14<=$I14),"",$V14*MAX(0,MIN($J14,50)-MAX($I14,30))/($J14-$I14)) -> 0 | Z14: =IF(OR($V14="",$I14="",$J14="",$J14<=$I14),"",$V14*MAX(0,MIN($J14,100)-MAX($I14,50))/($J14-$I14)) -> 0 | AA14: =IF($A14="","",IF(OR($C14="",$D14="",$D14<=$C14),"CHECK: depths missing, or bottom not below top",IF(COUNTIFS($A$6:$A$205,$A14,$C$6:$C$205,$C14)>1,"DUPLICATE slice",IF(COUNTIFS($A$6:$A$205,$A14,$C$6:$C$205,"<"&$D14,$D$6:$D$205,">"&$C14)>1,"OVERLAP with another slice",IF(AND($C14>0,COUNTIFS($A$6:$A$205,$A14,$D$6:$D$205,$C14)=0),"GAP above this slice",IF(OR($G14="",$H14=""),"CHECK: Core ID not in Core Log, or its compaction / diameter missing",IF(AND(IF(COUNTIFS('2. Plot & Core Log'!$B$6:$B$35,$A14,'2. Plot & Core Log'!$L$6:$L$35,">0")=0,"",SUMIFS('2. Plot & Core Log'!$L$6:$L$35,'2. Plot & Core Log'!$B$6:$B$35,$A14))<>"",$D14>IF(COUNTIFS('2. Plot & Core Log'!$B$6:$B$35,$A14,'2. Plot & Core Log'!$L$6:$L$35,">0")=0,"",SUMIFS('2. Plot & Core Log'!$L$6:$L$35,'2. Plot & Core Log'!$B$6:$B$35,$A14))),"CHECK: slice deeper than the core length on Sheet 2",IF(OR($M14="",$N14="",$O14=""),"AWAITING LAB (dry weight, carbon value or type)",IF(AND(UPPER($O14)<>"OC",UPPER($O14)<>"LOI"),IF(UPPER($O14)="TC","TC is not organic carbon — ask the lab for OC or IC","CHECK: type must be OC, TC or LOI"),IF($R14="",IF(AND(LOI_INTERCEPT<>"",LOI_SLOPE<>""),"CHECK: LOI below the range of the conversion equation (OC would be < 0)","CHECK: LOI conversion not set (Instructions tab)"),IF(OR($Q14<=0,$Q14>2.65,$R14>50),"CHECK: bulk density outside 0–2.65 g/cm3 or OC > 50%","OK"))))))))))) -> OK
A15: COW-S5 | B15: 10 | C15: 9 | D15: 10 | E15: LOI 550 °C, 5 h (no elemental C for this slice). Dry weight back-calculated from published bulk density. | F15: =IF(OR($C15="",$D15=""),"",$D15-$C15) -> 1 | G15: =IF($A15="","",IFERROR(INDEX('2. Plot & Core Log'!$M$6:$M$35,MATCH($A15,'2. Plot & Core Log'!$B$6:$B$35,0)),"")) -> 1 | H15: =IF($A15="","",IFERROR(INDEX('2. Plot & Core Log'!$S$6:$S$35,MATCH($A15,'2. Plot & Core Log'!$B$6:$B$35,0)),"")) -> 7.6 | I15: =IF(OR($C15="",$G15=""),"",$C15*$G15) -> 9 | J15: =IF(OR($D15="",$G15=""),"",$D15*$G15) -> 10 | K15: =IF(OR($F15="",$H15=""),"",PI()*(($H15/2)^2)*$F15) -> 45.364598 | M15: 75.76 | N15: 2.5 | O15: LOI | P15: =IF(OR($L15="",$M15="",$L15=0),"",(($L15-$M15)/$L15)*100) | Q15: =IF(OR($M15="",$K15="",$K15=0),"",$M15/$K15) -> 1.6700247 | R15: =IF(OR($N15="",$O15=""),"",IF(UPPER($O15)="OC",$N15,IF(UPPER($O15)="LOI",IF(OR(LOI_INTERCEPT="",LOI_SLOPE=""),"",IF(LOI_INTERCEPT+LOI_SLOPE*$N15<0,"",LOI_INTERCEPT+LOI_SLOPE*$N15)),""))) -> 0.603 | S15: =IF($R15="","",$R15*10) -> 6.03 | T15: =IF(OR($Q15="",$R15=""),"",$Q15*$R15/100) -> 0.010070249 | U15: =IF(OR($T15="",$F15=""),"",$T15*$F15) -> 0.010070249 | V15: =IF($U15="","",$U15*10) -> 0.10070249 | W15: =IF(OR($V15="",$I15="",$J15="",$J15<=$I15),"",$V15*MAX(0,MIN($J15,15)-MAX($I15,0))/($J15-$I15)) -> 0.10070249 | X15: =IF(OR($V15="",$I15="",$J15="",$J15<=$I15),"",$V15*MAX(0,MIN($J15,30)-MAX($I15,15))/($J15-$I15)) -> 0 | Y15: =IF(OR($V15="",$I15="",$J15="",$J15<=$I15),"",$V15*MAX(0,MIN($J15,50)-MAX($I15,30))/($J15-$I15)) -> 0 | Z15: =IF(OR($V15="",$I15="",$J15="",$J15<=$I15),"",$V15*MAX(0,MIN($J15,100)-MAX($I15,50))/($J15-$I15)) -> 0 | AA15: =IF($A15="","",IF(OR($C15="",$D15="",$D15<=$C15),"CHECK: depths missing, or bottom not below top",IF(COUNTIFS($A$6:$A$205,$A15,$C$6:$C$205,$C15)>1,"DUPLICATE slice",IF(COUNTIFS($A$6:$A$205,$A15,$C$6:$C$205,"<"&$D15,$D$6:$D$205,">"&$C15)>1,"OVERLAP with another slice",IF(AND($C15>0,COUNTIFS($A$6:$A$205,$A15,$D$6:$D$205,$C15)=0),"GAP above this slice",IF(OR($G15="",$H15=""),"CHECK: Core ID not in Core Log, or its compaction / diameter missing",IF(AND(IF(COUNTIFS('2. Plot & Core Log'!$B$6:$B$35,$A15,'2. Plot & Core Log'!$L$6:$L$35,">0")=0,"",SUMIFS('2. Plot & Core Log'!$L$6:$L$35,'2. Plot & Core Log'!$B$6:$B$35,$A15))<>"",$D15>IF(COUNTIFS('2. Plot & Core Log'!$B$6:$B$35,$A15,'2. Plot & Core Log'!$L$6:$L$35,">0")=0,"",SUMIFS('2. Plot & Core Log'!$L$6:$L$35,'2. Plot & Core Log'!$B$6:$B$35,$A15))),"CHECK: slice deeper than the core length on Sheet 2",IF(OR($M15="",$N15="",$O15=""),"AWAITING LAB (dry weight, carbon value or type)",IF(AND(UPPER($O15)<>"OC",UPPER($O15)<>"LOI"),IF(UPPER($O15)="TC","TC is not organic carbon — ask the lab for OC or IC","CHECK: type must be OC, TC or LOI"),IF($R15="",IF(AND(LOI_INTERCEPT<>"",LOI_SLOPE<>""),"CHECK: LOI below the range of the conversion equation (OC would be < 0)","CHECK: LOI conversion not set (Instructions tab)"),IF(OR($Q15<=0,$Q15>2.65,$R15>50),"CHECK: bulk density outside 0–2.65 g/cm3 or OC > 50%","OK"))))))))))) -> OK
A16: COW-S5 | B16: 11 | C16: 10 | D16: 12 | E16: LOI 550 °C, 5 h (no elemental C for this slice). Dry weight back-calculated from published bulk density. | F16: =IF(OR($C16="",$D16=""),"",$D16-$C16) -> 2 | G16: =IF($A16="","",IFERROR(INDEX('2. Plot & Core Log'!$M$6:$M$35,MATCH($A16,'2. Plot & Core Log'!$B$6:$B$35,0)),"")) -> 1 | H16: =IF($A16="","",IFERROR(INDEX('2. Plot & Core Log'!$S$6:$S$35,MATCH($A16,'2. Plot & Core Log'!$B$6:$B$35,0)),"")) -> 7.6 | I16: =IF(OR($C16="",$G16=""),"",$C16*$G16) -> 10 | J16: =IF(OR($D16="",$G16=""),"",$D16*$G16) -> 12 | K16: =IF(OR($F16="",$H16=""),"",PI()*(($H16/2)^2)*$F16) -> 90.729196 | M16: 158.78 | N16: 2.6 | O16: LOI | P16: =IF(OR($L16="",$M16="",$L16=0),"",(($L16-$M16)/$L16)*100) | Q16: =IF(OR($M16="",$K16="",$K16=0),"",$M16/$K16) -> 1.7500431 | R16: =IF(OR($N16="",$O16=""),"",IF(UPPER($O16)="OC",$N16,IF(UPPER($O16)="LOI",IF(OR(LOI_INTERCEPT="",LOI_SLOPE=""),"",IF(LOI_INTERCEPT+LOI_SLOPE*$N16<0,"",LOI_INTERCEPT+LOI_SLOPE*$N16)),""))) -> 0.635 | S16: =IF($R16="","",$R16*10) -> 6.35 | T16: =IF(OR($Q16="",$R16=""),"",$Q16*$R16/100) -> 0.011112773 | U16: =IF(OR($T16="",$F16=""),"",$T16*$F16) -> 0.022225547 | V16: =IF($U16="","",$U16*10) -> 0.22225547 | W16: =IF(OR($V16="",$I16="",$J16="",$J16<=$I16),"",$V16*MAX(0,MIN($J16,15)-MAX($I16,0))/($J16-$I16)) -> 0.22225547 | X16: =IF(OR($V16="",$I16="",$J16="",$J16<=$I16),"",$V16*MAX(0,MIN($J16,30)-MAX($I16,15))/($J16-$I16)) -> 0 | Y16: =IF(OR($V16="",$I16="",$J16="",$J16<=$I16),"",$V16*MAX(0,MIN($J16,50)-MAX($I16,30))/($J16-$I16)) -> 0 | Z16: =IF(OR($V16="",$I16="",$J16="",$J16<=$I16),"",$V16*MAX(0,MIN($J16,100)-MAX($I16,50))/($J16-$I16)) -> 0 | AA16: =IF($A16="","",IF(OR($C16="",$D16="",$D16<=$C16),"CHECK: depths missing, or bottom not below top",IF(COUNTIFS($A$6:$A$205,$A16,$C$6:$C$205,$C16)>1,"DUPLICATE slice",IF(COUNTIFS($A$6:$A$205,$A16,$C$6:$C$205,"<"&$D16,$D$6:$D$205,">"&$C16)>1,"OVERLAP with another slice",IF(AND($C16>0,COUNTIFS($A$6:$A$205,$A16,$D$6:$D$205,$C16)=0),"GAP above this slice",IF(OR($G16="",$H16=""),"CHECK: Core ID not in Core Log, or its compaction / diameter missing",IF(AND(IF(COUNTIFS('2. Plot & Core Log'!$B$6:$B$35,$A16,'2. Plot & Core Log'!$L$6:$L$35,">0")=0,"",SUMIFS('2. Plot & Core Log'!$L$6:$L$35,'2. Plot & Core Log'!$B$6:$B$35,$A16))<>"",$D16>IF(COUNTIFS('2. Plot & Core Log'!$B$6:$B$35,$A16,'2. Plot & Core Log'!$L$6:$L$35,">0")=0,"",SUMIFS('2. Plot & Core Log'!$L$6:$L$35,'2. Plot & Core Log'!$B$6:$B$35,$A16))),"CHECK: slice deeper than the core length on Sheet 2",IF(OR($M16="",$N16="",$O16=""),"AWAITING LAB (dry weight, carbon value or type)",IF(AND(UPPER($O16)<>"OC",UPPER($O16)<>"LOI"),IF(UPPER($O16)="TC","TC is not organic carbon — ask the lab for OC or IC","CHECK: type must be OC, TC or LOI"),IF($R16="",IF(AND(LOI_INTERCEPT<>"",LOI_SLOPE<>""),"CHECK: LOI below the range of the conversion equation (OC would be < 0)","CHECK: LOI conversion not set (Instructions tab)"),IF(OR($Q16<=0,$Q16>2.65,$R16>50),"CHECK: bulk density outside 0–2.65 g/cm3 or OC > 50%","OK"))))))))))) -> OK
A17: COW-S5 | B17: 12 | C17: 12 | D17: 14 | E17: LOI 550 °C, 5 h (no elemental C for this slice). Dry weight back-calculated from published bulk density. | F17: =IF(OR($C17="",$D17=""),"",$D17-$C17) -> 2 | G17: =IF($A17="","",IFERROR(INDEX('2. Plot & Core Log'!$M$6:$M$35,MATCH($A17,'2. Plot & Core Log'!$B$6:$B$35,0)),"")) -> 1 | H17: =IF($A17="","",IFERROR(INDEX('2. Plot & Core Log'!$S$6:$S$35,MATCH($A17,'2. Plot & Core Log'!$B$6:$B$35,0)),"")) -> 7.6 | I17: =IF(OR($C17="",$G17=""),"",$C17*$G17) -> 12 | J17: =IF(OR($D17="",$G17=""),"",$D17*$G17) -> 14 | K17: =IF(OR($F17="",$H17=""),"",PI()*(($H17/2)^2)*$F17) -> 90.729196 | M17: 157.87 | N17: 2.5 | O17: LOI | P17: =IF(OR($L17="",$M17="",$L17=0),"",(($L17-$M17)/$L17)*100) | Q17: =IF(OR($M17="",$K17="",$K17=0),"",$M17/$K17) -> 1.7400132 | R17: =IF(OR($N17="",$O17=""),"",IF(UPPER($O17)="OC",$N17,IF(UPPER($O17)="LOI",IF(OR(LOI_INTERCEPT="",LOI_SLOPE=""),"",IF(LOI_INTERCEPT+LOI_SLOPE*$N17<0,"",LOI_INTERCEPT+LOI_SLOPE*$N17)),""))) -> 0.603 | S17: =IF($R17="","",$R17*10) -> 6.03 | T17: =IF(OR($Q17="",$R17=""),"",$Q17*$R17/100) -> 0.01049228 | U17: =IF(OR($T17="",$F17=""),"",$T17*$F17) -> 0.020984559 | V17: =IF($U17="","",$U17*10) -> 0.20984559 | W17: =IF(OR($V17="",$I17="",$J17="",$J17<=$I17),"",$V17*MAX(0,MIN($J17,15)-MAX($I17,0))/($J17-$I17)) -> 0.20984559 | X17: =IF(OR($V17="",$I17="",$J17="",$J17<=$I17),"",$V17*MAX(0,MIN($J17,30)-MAX($I17,15))/($J17-$I17)) -> 0 | Y17: =IF(OR($V17="",$I17="",$J17="",$J17<=$I17),"",$V17*MAX(0,MIN($J17,50)-MAX($I17,30))/($J17-$I17)) -> 0 | Z17: =IF(OR($V17="",$I17="",$J17="",$J17<=$I17),"",$V17*MAX(0,MIN($J17,100)-MAX($I17,50))/($J17-$I17)) -> 0 | AA17: =IF($A17="","",IF(OR($C17="",$D17="",$D17<=$C17),"CHECK: depths missing, or bottom not below top",IF(COUNTIFS($A$6:$A$205,$A17,$C$6:$C$205,$C17)>1,"DUPLICATE slice",IF(COUNTIFS($A$6:$A$205,$A17,$C$6:$C$205,"<"&$D17,$D$6:$D$205,">"&$C17)>1,"OVERLAP with another slice",IF(AND($C17>0,COUNTIFS($A$6:$A$205,$A17,$D$6:$D$205,$C17)=0),"GAP above this slice",IF(OR($G17="",$H17=""),"CHECK: Core ID not in Core Log, or its compaction / diameter missing",IF(AND(IF(COUNTIFS('2. Plot & Core Log'!$B$6:$B$35,$A17,'2. Plot & Core Log'!$L$6:$L$35,">0")=0,"",SUMIFS('2. Plot & Core Log'!$L$6:$L$35,'2. Plot & Core Log'!$B$6:$B$35,$A17))<>"",$D17>IF(COUNTIFS('2. Plot & Core Log'!$B$6:$B$35,$A17,'2. Plot & Core Log'!$L$6:$L$35,">0")=0,"",SUMIFS('2. Plot & Core Log'!$L$6:$L$35,'2. Plot & Core Log'!$B$6:$B$35,$A17))),"CHECK: slice deeper than the core length on Sheet 2",IF(OR($M17="",$N17="",$O17=""),"AWAITING LAB (dry weight, carbon value or type)",IF(AND(UPPER($O17)<>"OC",UPPER($O17)<>"LOI"),IF(UPPER($O17)="TC","TC is not organic carbon — ask the lab for OC or IC","CHECK: type must be OC, TC or LOI"),IF($R17="",IF(AND(LOI_INTERCEPT<>"",LOI_SLOPE<>""),"CHECK: LOI below the range of the conversion equation (OC would be < 0)","CHECK: LOI conversion not set (Instructions tab)"),IF(OR($Q17<=0,$Q17>2.65,$R17>50),"CHECK: bulk density outside 0–2.65 g/cm3 or OC > 50%","OK"))))))))))) -> OK
... A50: COW-S7 | B50: 15 | C50: 18 | D50: 20 | E50: LOI 550 °C, 5 h (no elemental C for this slice). Dry weight back-calculated from published bulk density. | F50: =IF(OR($C50="",$D50=""),"",$D50-$C50) -> 2 | G50: =IF($A50="","",IFERROR(INDEX('2. Plot & Core Log'!$M$6:$M$35,MATCH($A50,'2. Plot & Core Log'!$B$6:$B$35,0)),"")) -> 1 | H50: =IF($A50="","",IFERROR(INDEX('2. Plot & Core Log'!$S$6:$S$35,MATCH($A50,'2. Plot & Core Log'!$B$6:$B$35,0)),"")) -> 7.6 | I50: =IF(OR($C50="",$G50=""),"",$C50*$G50) -> 18 | J50: =IF(OR($D50="",$G50=""),"",$D50*$G50) -> 20 | K50: =IF(OR($F50="",$H50=""),"",PI()*(($H50/2)^2)*$F50) -> 90.729196 | M50: 168.76 | N50: 2 | O50: LOI | P50: =IF(OR($L50="",$M50="",$L50=0),"",(($L50-$M50)/$L50)*100) | Q50: =IF(OR($M50="",$K50="",$K50=0),"",$M50/$K50) -> 1.8600407 | R50: =IF(OR($N50="",$O50=""),"",IF(UPPER($O50)="OC",$N50,IF(UPPER($O50)="LOI",IF(OR(LOI_INTERCEPT="",LOI_SLOPE=""),"",IF(LOI_INTERCEPT+LOI_SLOPE*$N50<0,"",LOI_INTERCEPT+LOI_SLOPE*$N50)),""))) -> 0.443 | S50: =IF($R50="","",$R50*10) -> 4.43 | T50: =IF(OR($Q50="",$R50=""),"",$Q50*$R50/100) -> 0.0082399805 | U50: =IF(OR($T50="",$F50=""),"",$T50*$F50) -> 0.016479961 | V50: =IF($U50="","",$U50*10) -> 0.16479961 | W50: =IF(OR($V50="",$I50="",$J50="",$J50<=$I50),"",$V50*MAX(0,MIN($J50,15)-MAX($I50,0))/($J50-$I50)) -> 0 | X50: =IF(OR($V50="",$I50="",$J50="",$J50<=$I50),"",$V50*MAX(0,MIN($J50,30)-MAX($I50,15))/($J50-$I50)) -> 0.16479961 | Y50: =IF(OR($V50="",$I50="",$J50="",$J50<=$I50),"",$V50*MAX(0,MIN($J50,50)-MAX($I50,30))/($J50-$I50)) -> 0 | Z50: =IF(OR($V50="",$I50="",$J50="",$J50<=$I50),"",$V50*MAX(0,MIN($J50,100)-MAX($I50,50))/($J50-$I50)) -> 0 | AA50: =IF($A50="","",IF(OR($C50="",$D50="",$D50<=$C50),"CHECK: depths missing, or bottom not below top",IF(COUNTIFS($A$6:$A$205,$A50,$C$6:$C$205,$C50)>1,"DUPLICATE slice",IF(COUNTIFS($A$6:$A$205,$A50,$C$6:$C$205,"<"&$D50,$D$6:$D$205,">"&$C50)>1,"OVERLAP with another slice",IF(AND($C50>0,COUNTIFS($A$6:$A$205,$A50,$D$6:$D$205,$C50)=0),"GAP above this slice",IF(OR($G50="",$H50=""),"CHECK: Core ID not in Core Log, or its compaction / diameter missing",IF(AND(IF(COUNTIFS('2. Plot & Core Log'!$B$6:$B$35,$A50,'2. Plot & Core Log'!$L$6:$L$35,">0")=0,"",SUMIFS('2. Plot & Core Log'!$L$6:$L$35,'2. Plot & Core Log'!$B$6:$B$35,$A50))<>"",$D50>IF(COUNTIFS('2. Plot & Core Log'!$B$6:$B$35,$A50,'2. Plot & Core Log'!$L$6:$L$35,">0")=0,"",SUMIFS('2. Plot & Core Log'!$L$6:$L$35,'2. Plot & Core Log'!$B$6:$B$35,$A50))),"CHECK: slice deeper than the core length on Sheet 2",IF(OR($M50="",$N50="",$O50=""),"AWAITING LAB (dry weight, carbon value or type)",IF(AND(UPPER($O50)<>"OC",UPPER($O50)<>"LOI"),IF(UPPER($O50)="TC","TC is not organic carbon — ask the lab for OC or IC","CHECK: type must be OC, TC or LOI"),IF($R50="",IF(AND(LOI_INTERCEPT<>"",LOI_SLOPE<>""),"CHECK: LOI below the range of the conversion equation (OC would be < 0)","CHECK: LOI conversion not set (Instructions tab)"),IF(OR($Q50<=0,$Q50>2.65,$R50>50),"CHECK: bulk density outside 0–2.65 g/cm3 or OC > 50%","OK"))))))))))) -> OK
